Workbook

Sheet Cover
B2: Unilever plc — Argentina & Türkiye Hyperinflation Model
C4: Description
C5: CFA Level II Financial Statement Analysis — Multinational Operations reading, illustrated with Unilever plc's real disclosed application of IAS 29 (Financial Reporting in Hyperinflationary Economies) to its Argentina (hyperinflationary since 1 Jul 2018) and Türkiye (hyperinflationary since 1 Jul 2022) subsidiaries. Local subsidiary accounts are a small fictional illustration calibrated to reproduce Unilever's own disclosed 2024 IAS 29 impact figures; see research_output.md.
C7: Period
C8: 2024 (calibrated) + 2025 (rolled-forward validation)
C10: Prepared by
C11: Hyperinflation Model Generator (bizplan)
C13: Classification
C14: Illustrative teaching model — not investment advice, not a reproduction of Unilever's actual subsidiary financial statements
C16: Methodology
C17: World A -- plain current-rate method (no inflation restatement): the baseline the IAS 29 impact is measured against -- the 'disappearing plant' case.
C18: World B -- US GAAP temporal method (remeasurement): non-monetary items at historical FX, monetary items at current FX, remeasurement gain/loss to income.
C19: World C -- actual IFRS treatment: IAS 29 inflation restatement, then IAS 21 translation of the restated figures at the closing rate (Unilever's own policy).
C20: See Argentina_Schedules / Turkiye_Schedules for the full restatement chain, Scenario_Comparison for World A/B/C side by side, Validation_2025 for the model's 2025 roll-forward vs. Unilever's real 2025 disclosure.

Sheet Assumptions
B2: Assumptions -- Local-Currency Inputs (disclosed/illustrative)
D4: 2024 | E4: 2025
C6: ARGENTINA -- ARS (hyperinflationary since 2018-07-01)
C7: Inflation index -- opening | D7: 100 | E7: 218
C8: Inflation index -- closing | D8: 218 | E8: 283.4
C9: FX rate -- opening (local/EUR) | D9: 850 | E9: 1010
C10: FX rate -- closing (local/EUR) | D10: 1010 | E10: 1450.36
C11: Revenue (nominal, local) | D11: 601159 | E11: 781506.7
C12: COGS (nominal, local) | D12: 356513.4 | E12: 463467.42
C13: Opex (nominal, local) | D13: 189757.1 | E13: 246684.23
C14: Depreciation (nominal, local) | D14: 28751.1 | E14: 37376.43
C15: Capex (nominal, local) | D15: 31626.2 | E15: 41114.06
C16: Non-monetary assets -- opening (prior-year restated) | D16: 404550.9 | E16: 886166
C17: Monetary assets -- closing | D17: 250000 | E17: 325000
C18: Monetary liabilities -- closing | D18: 657084.7 | E18: 854210.11
C19: Equity -- opening (prior-year restated) | D19: 297500 | E19: 479081.3
C21: TURKIYE -- TRY (hyperinflationary since 2022-07-01)
C22: Inflation index -- opening | D22: 100 | E22: 144
C23: Inflation index -- closing | D23: 144 | E23: 184.32
C24: FX rate -- opening (local/EUR) | D24: 33.5 | E24: 39.5
C25: FX rate -- closing (local/EUR) | D25: 39.5 | E25: 53.325
C26: Revenue (nominal, local) | D26: 64717.7 | E26: 82838.656
C27: COGS (nominal, local) | D27: 40983.2 | E27: 47540.512
C28: Opex (nominal, local) | D28: 21813.7 | E28: 25303.892
C29: Depreciation (nominal, local) | D29: 3305.1 | E29: 4230.528
C30: Capex (nominal, local) | D30: 3635.6 | E30: 4653.568
C31: Non-monetary assets -- opening (prior-year restated) | D31: 5685 | E31: 8583
C32: Monetary assets -- closing | D32: 8000 | E32: 10240
C33: Monetary liabilities -- closing | D33: 4302.5 | E33: 5507.2
C34: Equity -- opening (prior-year restated) | D34: 9380 | E34: 12280.5
C36: OTHER GROUP OPERATIONS (EUR, scenario-invariant)
C37: Revenue | D37: 58000 | E37: 58000
C38: COGS | D38: 28000 | E38: 28000
C39: Operating profit | D39: 8500 | E39: 8500
C40: Total assets | D40: 45000 | E40: 45000
C41: Equity | D41: 20000 | E41: 20000
C42: Non-monetary assets | D42: 22000 | E42: 22000
C43: Monetary gain/(loss) | D43: 0 | E43: 0

Sheet Argentina_Schedules
B2: Argentina (ARS) -- Hyperinflation Schedule Chain
D4: 2024 | E4: 2025
C6: 01 -- LOCAL FS (nominal, from Assumptions)
C7: Inflation index -- opening | D7: ='Assumptions'!D7 | E7: ='Assumptions'!E7
C8: Inflation index -- closing | D8: ='Assumptions'!D8 | E8: ='Assumptions'!E8
C9: FX rate -- opening (local/EUR) | D9: ='Assumptions'!D9 | E9: ='Assumptions'!E9
C10: FX rate -- closing (local/EUR) | D10: ='Assumptions'!D10 | E10: ='Assumptions'!E10
C11: Revenue (nominal, local) | D11: ='Assumptions'!D11 | E11: ='Assumptions'!E11
C12: COGS (nominal, local) | D12: ='Assumptions'!D12 | E12: ='Assumptions'!E12
C13: Opex (nominal, local) | D13: ='Assumptions'!D13 | E13: ='Assumptions'!E13
C14: Depreciation (nominal, local) | D14: ='Assumptions'!D14 | E14: ='Assumptions'!E14
C15: Capex (nominal, local) | D15: ='Assumptions'!D15 | E15: ='Assumptions'!E15
C16: Non-monetary assets -- opening (prior-year restated) | D16: ='Assumptions'!D16 | E16: ='Assumptions'!E16
C17: Monetary assets -- closing | D17: ='Assumptions'!D17 | E17: ='Assumptions'!E17
C18: Monetary liabilities -- closing | D18: ='Assumptions'!D18 | E18: ='Assumptions'!E18
C19: Equity -- opening (prior-year restated) | D19: ='Assumptions'!D19 | E19: ='Assumptions'!E19
C21: 02 -- INFLATION INDEX & FX (derived)
C22: Inflation index -- average (geometric mean) | D22: =SQRT(D7*D8) | E22: =SQRT(E7*E8)
C23: FX rate -- average (geometric mean) | D23: =SQRT(D9*D10) | E23: =SQRT(E9*E10)
C24: Restatement factor -- opening vintage (close/open) | D24: =D8/D7 | E24: =E8/E7
C25: Restatement factor -- in-year flows (close/avg) | D25: =D8/D22 | E25: =E8/E22
C26: Inflation-vs-FX wedge r (=f_avg x fx_avg/fx_close) | D26: =D25*D23/D10 | E26: =E25*E23/E10
C28: 03 -- IAS 29 RESTATEMENT (local currency, year-end purchasing power)
C29: Revenue, restated | D29: =D11*D25 | E29: =E11*E25
C30: COGS, restated | D30: =D12*D25 | E30: =E12*E25
C31: Opex, restated | D31: =D13*D25 | E31: =E13*E25
C32: Depreciation, restated | D32: =D14*D25 | E32: =E14*E25
C33: Operating profit, restated | D33: =D29-D30-D31-D32 | E33: =E29-E30-E31-E32
C34: Non-monetary assets, restated | D34: =D16*D24+D15*D25-D32 | E34: =E16*E24+E15*E25-E32
C35: Total assets, restated | D35: =D34+D17 | E35: =E34+E17
C36: Equity (opening), restated | D36: =D19*D24 | E36: =E19*E24
C37: Net monetary gain/(loss) -- balancing plug | D37: =(D35-D18)-D36-D33 | E37: =(E35-E18)-E36-E33
C39: 04 -- FX TRANSLATION -- World C (IAS 21, closing rate)
C40: Revenue (EUR) | D40: =D29/D10 | E40: =E29/E10
C41: COGS (EUR) | D41: =D30/D10 | E41: =E30/E10
C42: Opex (EUR) | D42: =D31/D10 | E42: =E31/E10
C43: Depreciation (EUR) | D43: =D32/D10 | E43: =E32/E10
C44: Operating profit (EUR) | D44: =D33/D10 | E44: =E33/E10
C45: Total assets (EUR) | D45: =D35/D10 | E45: =E35/E10
C46: Non-monetary assets (EUR) | D46: =D34/D10 | E46: =E34/E10
...

Sheet Turkiye_Schedules
B2: Turkiye (TRY) -- Hyperinflation Schedule Chain
D4: 2024 | E4: 2025
C6: 01 -- LOCAL FS (nominal, from Assumptions)
C7: Inflation index -- opening | D7: ='Assumptions'!D22 | E7: ='Assumptions'!E22
C8: Inflation index -- closing | D8: ='Assumptions'!D23 | E8: ='Assumptions'!E23
C9: FX rate -- opening (local/EUR) | D9: ='Assumptions'!D24 | E9: ='Assumptions'!E24
C10: FX rate -- closing (local/EUR) | D10: ='Assumptions'!D25 | E10: ='Assumptions'!E25
C11: Revenue (nominal, local) | D11: ='Assumptions'!D26 | E11: ='Assumptions'!E26
C12: COGS (nominal, local) | D12: ='Assumptions'!D27 | E12: ='Assumptions'!E27
C13: Opex (nominal, local) | D13: ='Assumptions'!D28 | E13: ='Assumptions'!E28
C14: Depreciation (nominal, local) | D14: ='Assumptions'!D29 | E14: ='Assumptions'!E29
C15: Capex (nominal, local) | D15: ='Assumptions'!D30 | E15: ='Assumptions'!E30
C16: Non-monetary assets -- opening (prior-year restated) | D16: ='Assumptions'!D31 | E16: ='Assumptions'!E31
C17: Monetary assets -- closing | D17: ='Assumptions'!D32 | E17: ='Assumptions'!E32
C18: Monetary liabilities -- closing | D18: ='Assumptions'!D33 | E18: ='Assumptions'!E33
C19: Equity -- opening (prior-year restated) | D19: ='Assumptions'!D34 | E19: ='Assumptions'!E34
C21: 02 -- INFLATION INDEX & FX (derived)
C22: Inflation index -- average (geometric mean) | D22: =SQRT(D7*D8) | E22: =SQRT(E7*E8)
C23: FX rate -- average (geometric mean) | D23: =SQRT(D9*D10) | E23: =SQRT(E9*E10)
C24: Restatement factor -- opening vintage (close/open) | D24: =D8/D7 | E24: =E8/E7
C25: Restatement factor -- in-year flows (close/avg) | D25: =D8/D22 | E25: =E8/E22
C26: Inflation-vs-FX wedge r (=f_avg x fx_avg/fx_close) | D26: =D25*D23/D10 | E26: =E25*E23/E10
C28: 03 -- IAS 29 RESTATEMENT (local currency, year-end purchasing power)
C29: Revenue, restated | D29: =D11*D25 | E29: =E11*E25
C30: COGS, restated | D30: =D12*D25 | E30: =E12*E25
C31: Opex, restated | D31: =D13*D25 | E31: =E13*E25
C32: Depreciation, restated | D32: =D14*D25 | E32: =E14*E25
C33: Operating profit, restated | D33: =D29-D30-D31-D32 | E33: =E29-E30-E31-E32
C34: Non-monetary assets, restated | D34: =D16*D24+D15*D25-D32 | E34: =E16*E24+E15*E25-E32
C35: Total assets, restated | D35: =D34+D17 | E35: =E34+E17
C36: Equity (opening), restated | D36: =D19*D24 | E36: =E19*E24
C37: Net monetary gain/(loss) -- balancing plug | D37: =(D35-D18)-D36-D33 | E37: =(E35-E18)-E36-E33
C39: 04 -- FX TRANSLATION -- World C (IAS 21, closing rate)
C40: Revenue (EUR) | D40: =D29/D10 | E40: =E29/E10
C41: COGS (EUR) | D41: =D30/D10 | E41: =E30/E10
C42: Opex (EUR) | D42: =D31/D10 | E42: =E31/E10
C43: Depreciation (EUR) | D43: =D32/D10 | E43: =E32/E10
C44: Operating profit (EUR) | D44: =D33/D10 | E44: =E33/E10
C45: Total assets (EUR) | D45: =D35/D10 | E45: =E35/E10
C46: Non-monetary assets (EUR) | D46: =D34/D10 | E46: =E34/E10
...

Sheet Consolidation
B2: 05 -- Parent Consolidation (World C -- actual IFRS treatment)
D4: 2024 | E4: 2025
C6: Revenue | D6: ='Argentina_Schedules'!D40+'Turkiye_Schedules'!D40+'Assumptions'!D37 | E6: ='Argentina_Schedules'!E40+'Turkiye_Schedules'!E40+'Assumptions'!E37
C7: COGS | D7: ='Argentina_Schedules'!D41+'Turkiye_Schedules'!D41+'Assumptions'!D38 | E7: ='Argentina_Schedules'!E41+'Turkiye_Schedules'!E41+'Assumptions'!E38
C8: Operating profit | D8: ='Argentina_Schedules'!D44+'Turkiye_Schedules'!D44+'Assumptions'!D39 | E8: ='Argentina_Schedules'!E44+'Turkiye_Schedules'!E44+'Assumptions'!E39
C9: Total assets | D9: ='Argentina_Schedules'!D45+'Turkiye_Schedules'!D45+'Assumptions'!D40 | E9: ='Argentina_Schedules'!E45+'Turkiye_Schedules'!E45+'Assumptions'!E40
C10: Non-monetary assets | D10: ='Argentina_Schedules'!D46+'Turkiye_Schedules'!D46+'Assumptions'!D42 | E10: ='Argentina_Schedules'!E46+'Turkiye_Schedules'!E46+'Assumptions'!E42
C11: Net monetary gain/(loss) | D11: ='Argentina_Schedules'!D47+'Turkiye_Schedules'!D47+'Assumptions'!D43 | E11: ='Argentina_Schedules'!E47+'Turkiye_Schedules'!E47+'Assumptions'!E43
C13: GROUP RATIOS
C14: Return on assets (Op. profit / Total assets) | D14: =D8/D9 | E14: =E8/E9
C15: Asset turnover (Revenue / Total assets) | D15: =D6/D9 | E15: =E6/E9

Sheet Scenario_Comparison
B2: World A / B / C Side-by-Side -- Argentina + Turkiye Combined (hyperinflationary subsidiaries only; see Consolidation for the full group)
C4: YEAR 2024
D5: World A -- Current Rate | E5: World B -- US GAAP Temporal | F5: World C -- IFRS (IAS29+21)
C6: Revenue | D6: ='Argentina_Schedules'!D52+'Turkiye_Schedules'!D52 | E6: ='Argentina_Schedules'!D52+'Turkiye_Schedules'!D52 | F6: ='Argentina_Schedules'!D40+'Turkiye_Schedules'!D40
C7: COGS | D7: ='Argentina_Schedules'!D53+'Turkiye_Schedules'!D53 | E7: ='Argentina_Schedules'!D53+'Turkiye_Schedules'!D53 | F7: ='Argentina_Schedules'!D41+'Turkiye_Schedules'!D41
C8: Operating profit | D8: ='Argentina_Schedules'!D56+'Turkiye_Schedules'!D56 | E8: ='Argentina_Schedules'!D56+'Turkiye_Schedules'!D56 | F8: ='Argentina_Schedules'!D44+'Turkiye_Schedules'!D44
C9: Non-monetary assets (PPE etc.) | D9: ='Argentina_Schedules'!D50/'Argentina_Schedules'!D10+'Turkiye_Schedules'!D50/'Turkiye_Schedules'!D10 | E9: ='Argentina_Schedules'!D61+'Turkiye_Schedules'!D61 | F9: ='Argentina_Schedules'!D46+'Turkiye_Schedules'!D46
C10: Total assets | D10: ='Argentina_Schedules'!D57+'Turkiye_Schedules'!D57 | E10: ='Argentina_Schedules'!D65+'Turkiye_Schedules'!D65 | F10: ='Argentina_Schedules'!D45+'Turkiye_Schedules'!D45
C11: Net monetary / remeasurement gain-(loss) | D11: ='Argentina_Schedules'!D58+'Turkiye_Schedules'!D58 | E11: ='Argentina_Schedules'!D66+'Turkiye_Schedules'!D66 | F11: ='Argentina_Schedules'!D47+'Turkiye_Schedules'!D47
C13: YEAR 2025
D14: World A -- Current Rate | E14: World B -- US GAAP Temporal | F14: World C -- IFRS (IAS29+21)
C15: Revenue | D15: ='Argentina_Schedules'!E52+'Turkiye_Schedules'!E52 | E15: ='Argentina_Schedules'!E52+'Turkiye_Schedules'!E52 | F15: ='Argentina_Schedules'!E40+'Turkiye_Schedules'!E40
C16: COGS | D16: ='Argentina_Schedules'!E53+'Turkiye_Schedules'!E53 | E16: ='Argentina_Schedules'!E53+'Turkiye_Schedules'!E53 | F16: ='Argentina_Schedules'!E41+'Turkiye_Schedules'!E41
C17: Operating profit | D17: ='Argentina_Schedules'!E56+'Turkiye_Schedules'!E56 | E17: ='Argentina_Schedules'!E56+'Turkiye_Schedules'!E56 | F17: ='Argentina_Schedules'!E44+'Turkiye_Schedules'!E44
C18: Non-monetary assets (PPE etc.) | D18: ='Argentina_Schedules'!E50/'Argentina_Schedules'!E10+'Turkiye_Schedules'!E50/'Turkiye_Schedules'!E10 | E18: ='Argentina_Schedules'!E61+'Turkiye_Schedules'!E61 | F18: ='Argentina_Schedules'!E46+'Turkiye_Schedules'!E46
C19: Total assets | D19: ='Argentina_Schedules'!E57+'Turkiye_Schedules'!E57 | E19: ='Argentina_Schedules'!E65+'Turkiye_Schedules'!E65 | F19: ='Argentina_Schedules'!E45+'Turkiye_Schedules'!E45
C20: Net monetary / remeasurement gain-(loss) | D20: ='Argentina_Schedules'!E58+'Turkiye_Schedules'!E58 | E20: ='Argentina_Schedules'!E66+'Turkiye_Schedules'!E66 | F20: ='Argentina_Schedules'!E47+'Turkiye_Schedules'!E47

Sheet Validation_2025
B2: Model 2025 Roll-Forward vs. Unilever's Real 2025 Disclosure
D4: Model | E4: Disclosed | F4: Gap (Model-Disclosed)
C5: ARGENTINA
C6: Total assets impact | D6: 183.66042 | E6: -199 | F6: 382.66042
C7: Turnover impact | D7: -31.336971 | E7: -90 | F7: 58.663029
C8: Operating profit impact | D8: -1.3624797 | E8: -54 | F8: 52.63752
C9: Net monetary gain/(loss) | D9: -23.773431 | E9: -46 | F9: 22.226569
C11: TURKIYE
C12: Total assets impact | D12: 46.109988 | E12: -20 | F12: 66.109988
C13: Turnover impact | D13: -47.418282 | E13: -16 | F13: -31.418282
C14: Operating profit impact | D14: -3.2992555 | E14: -46 | F14: 42.700745
C15: Net monetary gain/(loss) | D15: -113.31072 | E15: -10 | F15: -103.31072
C17: See examples/unilever/research_output.md for full discussion of why total-assets impact structurally cannot flip sign in this model, and why Turkiye's 2025 operating-profit assumption differs from a pure roll-forward.

Sheet Sources
B2: Sources
C4: Item | D4: Value | E4: Source | F4: Accessed | G4: URL
C5: Unilever plc — 2024 Annual Report on Form 20-F (hyperinflation accounting policy note) | D5: Argentina/Türkiye 2024 IAS29 impact table | E5: U.S. SEC EDGAR | F5: 2026-09-27 | G5: https://www.sec.gov/Archives/edgar/data/217410/000021741025000015/ul-20241231.htm
C6: Unilever plc — 2025 Annual Report on Form 20-F (hyperinflation accounting policy note) | D6: Argentina/Türkiye 2025 IAS29 impact table | E6: U.S. SEC EDGAR | F6: 2026-09-27 | G6: https://www.sec.gov/Archives/edgar/data/217410/000021741026000007/ul-20251231.htm
C7: Unilever plc — Annual Report and Accounts 2025 (Excel workbook) | D7: Consolidated financial statements | E7: Unilever plc investor relations | F7: 2026-09-27 | G7: https://www.unilever.com/investors/annual-report-and-accounts/
C8: IAS 29 Financial Reporting in Hyperinflationary Economies — restatement mechanics | D8: Monetary items not restated; non-monetary restated by price index; net monetary gain/loss recognized in P&L | E8: IFRS Foundation | F8: 2026-09-27
C9: IAS 21 The Effects of Changes in Foreign Exchange Rates — §42-43 | D9: Restated hyperinflationary FS translated at the closing rate (not average) | E9: IFRS Foundation | F9: 2026-09-27
C10: Coca-Cola FEMSA, S.A.B. de C.V. — 2025 Annual Report on Form 20-F | D10: Argentina net monetary position gain, H1 2025 vs H1 2024 | E10: U.S. SEC EDGAR | F10: 2026-09-27 | G10: https://www.sec.gov/Archives/edgar/data/910631/000162828026025313/kof-20251231.htm
C11: BBVA — 2023 Annual Report on Form 20-F | D11: Türkiye net monetary loss + inflation-linked-bond revaluation gain, FY2023/FY2022 | E11: U.S. SEC EDGAR | F11: 2026-09-27 | G11: https://www.sec.gov/Archives/edgar/data/842180/000084218024000007/bbva-20231231.htm
C12: IFRS Interpretations Committee — Assessing Indicators of Hyperinflationary Economies, July 2025 agenda decision | D12: Qualitative-indicator weighting; no new standard-setting project | E12: IFRS Foundation | F12: 2026-09-27 | G12: https://www.ifrs.org/projects/completed-projects/2025/assessing-indicators-of-hyperinflationary-economies-IAS-29/
C13: EY — Hyperinflationary economies (updated April 2026) | D13: Current list: Argentina, Türkiye, Haiti, Iran, Lebanon, Malawi, South Sudan, Sudan, Venezuela, Zimbabwe | E13: EY | F13: 2026-09-27 | G13: https://www.ey.com/en_lt/technical/ifrs-technical-resources/hyperinflationary-economies-updated-april-2026
C14: Colgate-Palmolive Company — Form 10-K FY2025 | D14: Argentina/Türkiye/Nigeria named 'highly inflationary'; no material impact disclosed | E14: U.S. SEC EDGAR | F14: 2026-09-27 | G14: https://www.sec.gov/Archives/edgar/data/21665/000002166526000006/cl-20251231.htm
C15: Reckitt Benckiser Group plc — Annual Report and Accounts 2025 (Financial Statements) | D15: Exchange-and-hyperinflation LFL revenue reconciling item, FY2025/FY2024; Argentina divestment (Essential Home sale, 31 Dec 2025) | E15: Reckitt Benckiser plc investor relations | F15: 2026-09-27 | G15: https://www.reckitt.com/investors/latest-annual-report/
